{
  "comments": [
    {
      "unresolved": false,
      "key": {
        "uuid": "834524f5_905e4caf",
        "filename": "/PATCHSET_LEVEL",
        "patchSetId": 1
      },
      "lineNbr": 0,
      "author": {
        "id": 1002666
      },
      "writtenOn": "2023-12-02T00:18:57Z",
      "side": 1,
      "message": "Just FYI, with change Ib0595628 applied on stable-3.5, I no longer get this error.",
      "revId": "13843ebf144a0c64771e4eb0c5245b2977ab676d",
      "serverId": "173816e5-2b9a-37c3-8a2e-48639d4f1153"
    }
  ]
}